Workbook

Sheet Use Case Tracker
A1: UC ID | B1: UC Name | C1: Main Flow | D1: Module | E1: Primary Actor | F1: Description / Goal | G1: Priority | H1: Status | I1: Owner | J1: Related Rule ID | K1: Notes | L1: Final Scope Decision
A2: UC01 | B2: Manage Subscription Plans and Feature Access | C2: Supporting Admin/Docker | D2: Subscription | E2: Admin | F2: Admin creates/updates/deactivates Free, Plus and Premium plans. Paid plans are billed annually only. Each plan defines yearly price and feature access such as finance reports, AI insights, SOS safety features, wearable support, storage and export capability. | G2: Must-have | H2: Not Started | J2: BR-SUB-01, BR-SUB-02, BR-SUB-03, BR-SUB-04, BR-SUB-08 | K2: Annual-only billing for paid plans. Monthly billing is out of scope for MVP. | L2: Keep
A3: UC02 | B3: Manage Family Workspaces and Subscription Status | C3: Supporting Admin/Docker | D3: Admin | E3: Admin | F3: Admin views workspaces, main Family Manager, subscription and activation status. | G3: Must-have | H3: Not Started | J3: BR-SUB-01, BR-WS-02 | L3: Keep
A4: UC03 | B4: Manage User Account Access | C4: Supporting Admin/Docker | D4: Admin | E4: Admin | F4: Admin locks/unlocks/restricts/restores user access when needed. | G4: Must-have | H4: Not Started | J4: BR-ADM-01, BR-AUTH-02 | L4: Keep
A5: UC04 | B5: Monitor Workspace Activation Status | C5: Supporting Admin/Docker | D5: Admin | E5: Admin | F5: Admin checks active/pending/suspended/failed/expired workspace states. | G5: Must-have | H5: Not Started | J5: BR-WS-02, BR-DEP-01 | L5: Keep
A6: UC05 | B6: View Basic Service Status | C6: Supporting Admin/Docker | D6: Admin | E6: Admin | F6: Admin views basic demo service status such as Backend, Admin Web, API and Database. | G6: Should-have | H6: Not Started | J6: BR-DEP-01, BR-FUT-01 | L6: Keep
A7: UC06 | B7: View Workspace Provisioning Logs | C7: Supporting Admin/Docker | D7: Admin | E7: Admin | F7: Admin views basic provisioning logs for workspace activation/demo startup failures. | G7: Should-have | H7: Not Started | J7: BR-DEP-01 | L7: Keep
A8: UC07 | B8: Retry Workspace Provisioning | C8: Supporting Admin/Docker | D8: Admin | E8: Admin | F8: Admin retries workspace activation/provisioning when a demo setup fails. | G8: Should-have | H8: Not Started | J8: BR-DEP-01 | L8: Keep
A9: UC08 | B9: View Basic Subscription Summary | C9: Supporting Admin/Docker | D9: Admin | E9: Admin | F9: Admin views a basic subscription summary only; advanced charts/export are Future. | G9: Could-have | H9: Not Started | J9: BR-SUB-01, BR-FUT-01 | L9: Could-have / Do after core
A10: UC09 | B10: Complete Family Onboarding Form - Account Info | C10: Flow 1 | D10: Auth | E10: Onboarding User / Family Representative | F10: Enter account registration information as part of the Family Onboarding Form. (Create Account Info -> Create Family Workspace info) | G10: Must-have | H10: Not Started | J10: BR-AUTH-01, BR-AUTH-03 | K10: Account info is collected before workspace setup. If email/phone already exists, system should redirect user to login/forgot password or resend verification if unverified. | L10: Keep
A11: UC10 | B11: Verify Account | C11: Flow 1 | D11: Auth | E11: Onboarding User / Family Representative | F11: Verify account after onboarding submission if verification is required before full workspace activation. | G11: Must-have | H11: Not Started | J11: BR-AUTH-01 | K11: Verification can be email/phone/code or simulated for demo. | L11: Keep
A12: UC11 | B12: Login / Logout | C12: Flow 1 | D12: Auth | E12: All Users | F12: Login or logout after account/workspace onboarding is completed. | G12: Must-have | H12: Not Started | J12: BR-AUTH-02 | K12: Login may be automatic after successful onboarding depending on implementation. | L12: Keep
A13: UC12 | B13: Create Family Workspace with Default Plan | C13: Flow 1 | D13: Family | E13: Onboarding User / Family Representative | F13: Submit family information in the onboarding form; system creates the Family Workspace, applies the default Free/Basic subscription status, and assigns the creator as the only main Family Manager. | G13: Must-have | H13: Not Started | J13: BR-WS-01, BR-WS-02, BR-SUB-01, BR-ROLE-01 | K13: This UC is triggered by the same Family Onboarding Form, not a fully separate manual flow. | L13: Keep
A14: UC13 | B14: Join Family via Invitation Link | C14: Flow 1 | D14: Family | E14: Invited User | F14: Join an existing Family Workspace through a valid invitation link after login/register. | G14: Must-have | H14: Not Started | J14: BR-INV-01 | K14: Used for invited members, not for the first Family Manager. | L14: Keep
A15: UC14 | B15: Manage Family Profile | C15: Flow 2 | D15: Family | E15: Family Manager | F15: Manage Family Profile | G15: Must-have | H15: Not Started | J15: BR-ROLE-01 | L15: Keep
A16: UC15 | B16: Invite Family Member | C16: Flow 2 | D16: Family | E16: Family Manager | F16: Invite Family Member | G16: Must-have | H16: Not Started | J16: BR-INV-01, BR-ROLE-01 | L16: Keep
A17: UC16 | B17: Manage Family Invitations | C17: Flow 2 | D17: Family | E17: Family Manager | F17: Manage Family Invitations | G17: Should-have | H17: Not Started | J17: BR-INV-01 | L17: Keep
A18: UC17 | B18: Manage Member Role and Relationship | C18: Flow 2 | D18: Family | E18: Family Manager | F18: Manage Member Role and Relationship | G18: Must-have | H18: Not Started | J18: BR-ROLE-03, BR-ROLE-04 | L18: Keep
A19: UC18 | B19: Grant or Revoke Deputy Permission | C19: Flow 2 | D19: Family | E19: Family Manager | F19: Grant or Revoke Deputy Permission | G19: Must-have | H19: Not Started | J19: BR-ROLE-02, BR-ROLE-01 | L19: Keep
A20: UC19 | B20: Remove or Deactivate Family Member | C20: Flow 2 | D20: Family | E20: Family Manager | F20: Remove or Deactivate Family Member | G20: Must-have | H20: Not Started | J20: BR-ROLE-01 | L20: Keep
A21: UC20 | B21: View Family Member List and Details | C21: Flow 2 | D21: Family | E21: Family Manager | F21: View Family Member List and Details | G21: Must-have | H21: Not Started | J21: BR-ROLE-03, BR-ROLE-04 | L21: Keep
A22: UC21 | B22: View Member Financial Profile Summary | C22: Flow 3 | D22: Finance | E22: Family Manager | F22: View member financial profile summary such as income status and aggregated planning data based on permission; Family Manager does not directly edit each member's private income/expense by default. | G22: Must-have | H22: Not Started | J22: BR-FIN-05, BR-FIN-06 | K22: Manager views summary for planning, not direct personal data control. | L22: Keep
A23: UC22 | B23: Set Personal Income and Expense | C23: Flow 3 | D23: Finance | E23: Family Member | F23: Family Member sets or updates personal income status, expected income, actual income, expected personal expense and actual personal expense. | G23: Must-have | H23: Not Started | J23: BR-FIN-05, BR-FIN-06, BR-AUTH-02 | K23: Each member owns their personal finance declaration. | L23: Keep
A24: UC23 | B24: Manage Shared Expense Categories | C24: Flow 3 | D24: Finance | E24: Family Manager / Family Member with delegated Deputy permission | F24: Manage shared family expense categories such as rent, electricity, water, food and school fees. | G24: Should-have | H24: Not Started | J24: BR-FIN-05 | K24: Shared categories are family-level, not member-private. | L24: Keep
A25: UC24 | B25: Set Expected Shared Family Income / Fund | C25: Flow 3 | D25: Finance | E25: Family Manager | F25: Set expected shared family income or family fund planning values, excluding private member income that members declare themselves. | G25: Must-have | H25: Not Started | J25: BR-FIN-05, BR-FIN-06 | K25: Use for common fund, shared contribution, or family-level income planning. | L25: Keep
A26: UC25 | B26: Set Expected Shared Family Expenses | C26: Flow 3 | D26: Finance | E26: Family Manager | F26: Set expected shared family expenses such as rent, utilities, food, school fees or other common household expenses. | G26: Must-have | H26: Not Started | J26: BR-FIN-05 | K26: Manager controls family-level shared expenses. | L26: Keep
A27: UC26 | B27: View Planned Family Budget | C27: Flow 3 | D27: Finance | E27: Family Manager | F27: View planned family budget calculated from member-declared personal income/expense and manager-defined shared family income/expense. | G27: Must-have | H27: Not Started | J27: BR-FIN-05, BR-FIN-06 | K27: Respect privacy/permission when showing details. | L27: Keep
A28: UC27 | B28: Record Actual Personal Income and Expense | C28: Flow 3 | D28: Finance | E28: Family Member | F28: Family Member records actual personal income and personal expense for their own financial tracking if allowed. | G28: Must-have | H28: Not Started | J28: BR-FIN-05, BR-FIN-06 | K28: Core finance scope after Review 1: budget planning, actual spending tracking, planned-vs-actual comparison and budget alerts. | L28: Keep
A29: UC28 | B29: Record Actual Shared Family Expense | C29: Flow 3 | D29: Finance | E29: Family Manager / Family Member with delegated Deputy permission | F29: Record actual shared family expense against the family fund ledger for tracking/planned-vs-actual reporting. The system does not hold or pay real money. | G29: Must-have | H29: Not Started | J29: BR-FIN-01, BR-FIN-04, BR-FIN-07 | K29: Shared actual expense is recorded in the family fund ledger only; no real money is held by the system. | L29: Keep
A30: UC29 | B30: View Actual Finance and Family Fund Report | C30: Flow 3 | D30: Finance | E30: Family Manager / Family Member with delegated Deputy permission | F30: View actual shared finance, family fund balance, and planned-vs-actual comparison; personal details are shown only according to privacy/permission rules. | G30: Must-have | H30: Not Started | J30: BR-FIN-01, BR-FIN-05, BR-FIN-06, BR-FIN-07 | K30: Report focuses on planned-vs-actual, fund ledger balance and privacy-aware finance summaries. | L30: Keep
A31: UC30 | B31: View Budget Alerts | C31: Flow 3 | D31: Finance | E31: Family Manager / Family Member with delegated Deputy permission | F31: View alerts when actual shared expenses exceed plan or family fund has shortage risk. | G31: Must-have | H31: Not Started | J31: BR-FIN-05, BR-FIN-06 | K31: Budget alerts are part of the core finance value after Review 1. | L31: Keep
A32: UC31 | B32: Manage Family Fund Ledger | C32: Flow 3 | D32: Finance / Family Fund | E32: Family Manager / Family Member with delegated Deputy permission | F32: Manage internal family fund ledger records for shared family planning, allowance and reward tracking. This is not a real e-wallet. | G32: Must-have | H32: Not Started | J32: BR-FIN-01, BR-FIN-04, BR-FIN-07, BR-FIN-08 | K32: This replaces the old top-up wallet concept. It is a ledger record, not a payment transaction. | L32: Keep, standardized as internal ledger scope after Review 1
A33: UC32 | B33: Record Family Fund Contribution | C33: Flow 3 | D33: Finance / Family Fund | E33: Family Manager / Family Member with delegated Deputy permission | F33: Record a contribution entry to the family fund ledger for planning and tracking purposes only. | G33: Must-have | H33: Not Started | J33: BR-FIN-01, BR-FIN-04, BR-FIN-07, BR-FIN-08 | K33: This replaces Record Family Fund Contribution. It is a ledger record, not a payment transaction. | L33: Keep, standardized as internal ledger scope after Review 1
... A37: UC36 | B37: View Family Fund and Allowance History | C37: Flow 3 | D37: Finance / Family Fund | E37: Family Manager / Family Member | F37: View family fund ledger, internal allowance, reward and spending support request history according to permission. | G37: Must-have | H37: Not Started | J37: BR-FIN-04, BR-FIN-06, BR-FIN-07 | K37: Transaction history means internal ledger history, not bank/payment transaction history. | L37: Keep, renamed from Family Fund Ledger history
A38: UC37 | B38: Manage Household Task Categories | C38: Flow 4 | D38: Task | E38: Family Manager / Family Member with delegated Deputy permission | F38: Manage Household Task Categories | G38: Should-have | H38: Not Started | J38: BR-TASK-01 | L38: Keep
A39: UC38 | B39: Create Ad-hoc Task | C39: Flow 4 | D39: Task | E39: Family Manager / Family Member with delegated Deputy permission | F39: Create Ad-hoc Task | G39: Must-have | H39: Not Started | J39: BR-TASK-01 | L39: Keep
A40: UC39 | B40: Create Recurring Mandatory Task | C40: Flow 4 | D40: Task | E40: Family Manager / Family Member with delegated Deputy permission | F40: Create Recurring Mandatory Task | G40: Must-have | H40: Not Started | J40: BR-TASK-01, BR-TASK-02 | L40: Keep
A41: UC40 | B41: Assign or Reassign Household Task | C41: Flow 4 | D41: Task | E41: Family Manager / Family Member with delegated Deputy permission | F41: Assign or Reassign Household Task | G41: Must-have | H41: Not Started | J41: BR-TASK-02 | L41: Keep
A42: UC41 | B42: Report Task Unavailability | C42: Flow 4 | D42: Task | E42: Family Member | F42: Report Task Unavailability | G42: Must-have | H42: Not Started | J42: BR-TASK-02 | L42: Keep
A43: UC42 | B43: Handle Recurring Task Takeover | C43: Flow 4 | D43: Task | E43: System / Family Manager / Family Member with delegated Deputy permission | F43: Handle Recurring Task Takeover | G43: Must-have | H43: Not Started | J43: BR-TASK-02 | L43: Keep
...

Sheet Main Core Flow Mapping
A1: Flow ID | B1: Flow Name | C1: Flow Type | D1: Business Goal | E1: Related UC IDs | F1: Main Actor | G1: Main Module | H1: Priority | I1: Owner | J1: Demo Scenario / Notes
A2: F1 | B2: Account Registration & Family Workspace Setup | C2: Core | D2: Let a user register/login first, then guide them to either create a new Family Workspace or join an existing one by invitation link before entering the dashboard. | E2: UC09-UC13; UC01-UC04 | F2: Guest / User / Family Representative / Invited User | G2: Auth, Family, Subscription | H2: Must-have | I2: Nhật | J2: Register/Login -> verify if required -> check workspace membership -> create new workspace or join by invitation -> assign role -> apply default plan for new workspace -> enter dashboard.
A3: F2 | B3: Member, Relationship & Delegated Permission Management | C3: Core | D3: Manage invitations, workspace members, family relationship, member status and delegated Deputy permission within one Family Workspace. | E3: UC13-UC20 | F3: Family Manager / Invited User | G3: Family, Member, Permission | H3: Must-have | I3: Nhật | J3: Invite member -> user joins workspace -> manager updates relationship/role -> grant or revoke delegated permission -> view or deactivate member.
A4: F3 | B4: Family Finance Planning, Fund Ledger and Goal-based Budgeting | C4: Core | D4: Manage family income/expense records, finance model, finance jars, essential/non-essential spending, family financial goals, planned-vs-actual reports, budget/goal risk alerts, and reward allocation without holding real user money. | E4: UC21-UC36; UC82-UC91 | F4: Family Manager / Family Member | G4: Finance, Family Fund Ledger, Goal-based Budgeting, AI Insight | H4: Must-have | J4: Select model -> configure jars -> record/categorize transactions -> create goal -> track progress -> view risk alerts -> allocate reward to jar/goal -> optional AI/OCR suggestion.
A5: F4 | B5: Household Task Coordination and Reward Settlement Management | C5: Core | D5: Create, assign, complete and approve household tasks; then create reward settlement record, mark external settlement, confirm member receipt or handle dispute. | E5: UC37-UC49 | F5: Family Manager / Family Member | G5: Task, Reward Settlement | H5: Must-have | J5: Create task -> assign -> submit proof -> approve task -> create pending reward settlement -> manager marks external settlement -> member confirms received or disputes -> view history.
A6: F5 | B6: SOS Alert, Wearable Safety and Safety Response Management | C6: Core | D6: Trigger SOS from mobile or wearable/safety device, notify family, confirm safety, resolve/cancel, track basic location during active SOS and store basic route/history. | E6: UC50-UC59 | F6: All Family Members | G6: SOS, Notification, Location, Wearable | H6: Must-have | J6: Mobile/device SOS -> notify family -> track active SOS location -> confirm safety -> resolve -> view history. Wearable can be simulated.
A7: SF4 | B7: Family Location Sharing and Member Tracking | C7: Supporting | D7: Allow members to opt in/out of normal location sharing, record routine location points from mobile/wearable, and let authorized family members view latest/basic location history without mixing it with SOS routes. | E7: UC79-UC81 | F7: Family Member / Authorized Family Member | G7: Location, Family, Wearable | H7: Should-have | J7: Enable sharing -> app/device sends location point -> authorized viewer opens family map -> system returns latest location/history. Normal tracking uses MemberLocationPoint; active SOS route uses SOSLocationPoint.
A8: SF1 | B8: Family Communication, Calendar and Album | C8: Supporting | D8: Support family coordination through notifications, basic chat, announcement, calendar, shared album and optional member tagging. | E8: UC60-UC64; UC70-UC75 | F8: All Family Members | G8: Communication, Calendar, Album | H8: Could-have | J8: Keep basic only; album tagging is optional; face clustering is not core MVP.
A9: SF2 | B9: AI-assisted Family Insight | C9: Supporting | D9: Provide AI assistant answers, finance summaries, task summaries and budget/saving suggestions based only on data the current user is allowed to view. | E9: UC65-UC68 | F9: All Family Members | G9: AI, Finance, Task, Reward, Reminder | H9: Should-have | J9: AI summarizes and suggests only; it does not make automatic decisions or update finance/task/SOS data.
A10: SF3 | B10: Subscription Plan and Feature Access Management | C10: Supporting | D10: View plan, compare Free/Plus/Premium, upgrade/renew subscription, handle expired plan and control feature access by plan. | E10: UC76-UC78 | F10: Family Manager / System | G10: Subscription, Payment, Feature Access | H10: Should-have | J10: Payment is only for subscription, not Family Fund Ledger, allowance or reward settlement.

Sheet Business Rule & Permission
A1: Rule ID | B1: Category | C1: Business Rule | D1: Applies To | E1: Can Delegate to Deputy? | F1: Related UC | G1: Module | H1: Priority | I1: Status | J1: Notes
A2: BR-ROLE-01 | B2: Role | C2: Each Family Workspace has only one main Family Manager. | D2: Family Workspace | E2: No | F2: UC12, UC17, UC18 | G2: Family | H2: Must-have | I2: Not Started | J2: Critical review point.
A3: BR-ROLE-02 | B3: Role | C3: Deputy is not a separate actor; it is delegated permission for a Family Member. | D3: Family Manager, Family Member | E3: N/A | F3: UC18 | G3: Permission | H3: Must-have | I3: Not Started | J3: Use wording: Family Member with delegated Deputy permission.
A4: BR-ROLE-03 | B4: Relationship | C4: Relationship describes family relation only and does not grant system permission. | D4: Family Member | E4: No | F4: UC17, UC20 | G4: Family | H4: Must-have | I4: Not Started | J4: Examples: father, mother, child, spouse, grandparent.
A5: BR-ROLE-04 | B5: Relationship | C5: Each member should have both role and relationship. | D5: Family Member | E5: No | F5: UC17, UC20 | G5: Family | H5: Must-have | I5: Not Started | J5: Useful for ERD and validation.
A6: BR-INV-01 | B6: Invitation | C6: Invited users join an existing family only through a valid invitation link. | D6: Invited User | E6: No | F6: UC13, UC15, UC16 | G6: Family | H6: Must-have | I6: Not Started | J6: Token must be valid and not expired/canceled.
A7: BR-AUTH-01 | B7: Authentication | C7: Users must register and verify their account before using protected family functions. | D7: Onboarding User / Family Representative | E7: No | F7: UC09, UC10 | G7: Auth | H7: Must-have | I7: Not Started | J7: Basic onboarding rule.
A8: BR-AUTH-02 | B8: Authorization | C8: Users can access resources only according to role, delegated permission and Family Workspace context. | D8: All Users | E8: No | F8: UC11 and protected UCs | G8: Auth / Permission | H8: Must-have | I8: Not Started | J8: Backend guard rule for all protected APIs.
A9: BR-AUTH-03 | B9: Authentication | C9: Email/phone number must be unique in the system. If an account already exists, the system must not create a duplicated account. | D9: Guest / User | E9: No | F9: UC09 | G9: Auth | H9: Must-have | I9: Not Started | J9: Existing verified account should be redirected to login or forgot password; existing unverified account can resend verification.
A10: BR-WS-01 | B10: Workspace | C10: The first user who creates a Family Workspace becomes the only main Family Manager. | D10: Onboarding User / Family Representative | E10: No | F10: UC12 | G10: Family | H10: Must-have | I10: Not Started | J10: Critical review point.
A11: BR-WS-02 | B11: Workspace | C11: A Family Workspace can be fully used only when subscription and activation status are valid. | D11: Family Workspace | E11: No | F11: UC04, UC12 | G11: Subscription / Workspace | H11: Must-have | I11: Not Started | J11: Supports onboarding and Admin workspace monitoring.
A12: BR-SUB-01 | B12: Subscription | C12: Subscription plans are limited to Free, Plus and Premium in current scope. Paid plans are annual-only. | D12: Admin, Family Manager | E12: No | F12: UC01, UC12, UC76-UC78 | G12: Subscription | H12: Must-have | I12: Not Started | J12: Plans are differentiated by feature access, not mainly by member count.
... A58: BR-AI-05 | B58: AI / Finance | C58: AI finance insight only summarizes and suggests; it cannot automatically change budgets, ledger records, rewards or SOS status. | D58: AI Assistant, System | E58: No | F58: UC65-UC68 | G58: AI / Finance | H58: Must-have | I58: Not Started | J58: Keeps AI as advisory feature.
A59: 54 | B59: BR-FIN-MODEL-01 | C59: Finance Model | D59: Family can select a finance model such as 5 Jars, 80/20, or Custom model for budgeting and allocation. | E59: Family Manager, delegated Deputy member | F59: Yes | G59: UC82, UC83 | H59: Finance / Planning Model | I59: Must-have | J59: Added from 02/06 mentor note about using a finance management model.
A60: 55 | B60: BR-FIN-JAR-01 | C60: Finance Jar / Fund | D60: Each finance jar/fund has name, purpose, allocation percentage or threshold, and can be used for budgeting or goal tracking. | E60: Family Manager, delegated Deputy member, System | F60: Yes | G60: UC83, UC87, UC90 | H60: Finance / Jar | I60: Must-have | J60: Example jars: essential, non-essential, saving goal, education, emergency.
A61: 56 | B61: BR-FIN-CAT-01 | C61: Finance Category | D61: Each income or expense record should be categorized into a finance category/jar for reporting, alerting and AI suggestion. | E61: Family Manager, Family Member, System | F61: No | G61: UC84, UC91 | H61: Finance / Category | I61: Must-have | J61: Manual classification is Must-have; AI/OCR suggestion is optional.
A62: 57 | B62: BR-FIN-CAT-02 | C62: Finance Category | D62: Each expense should be marked as Essential or Non-essential to support spending control, saving suggestions and goal-risk alerts. | E62: Family Manager, Family Member, System | F62: No | G62: UC85, UC89, UC91 | H62: Finance / Category | I62: Must-have | J62: Essential: food, utilities, tuition. Non-essential: entertainment, games, optional shopping.
A63: 58 | B63: BR-FIN-GOAL-01 | C63: Financial Goal | D63: Financial goal must have target amount, deadline, related fund, current progress and monthly contribution target. | E63: Family Manager, delegated Deputy member, System | F63: Yes | G63: UC86, UC87, UC88 | H63: Finance / Goal | I63: Must-have | J63: Example: buy a 30M VND motorbike by year-end.
A64: 59 | B64: BR-FIN-ALERT-01 | C64: Finance Alert | D64: System alerts when spending exceeds threshold, non-essential spending is too high, or financial goal progress is at risk. | E64: System, Family Manager, Family Member | F64: No | G64: UC30, UC88, UC89 | H64: Finance / Alert | I64: Must-have | J64: Extends Budget Alerts into Budget and Goal Risk Alerts.
A65: 60 | B65: BR-REW-JAR-01 | C65: Reward / Finance Jar | D65: Task reward should be allocated to a finance jar or goal fund after member confirms reward receipt. | E65: Family Member, System | F65: No | G65: UC47, UC90 | H65: Reward Settlement / Finance | I65: Must-have | J65: Added from 02/06 mentor note: reward must know which jar it belongs to.
A66: 61 | B66: BR-AI-FIN-01 | C66: AI / OCR / Finance | D66: AI/OCR only suggests category, jar, essential/non-essential type or saving advice; user must confirm the final finance record. | E66: AI Assistant, System, User | F66: No | G66: UC91, UC65-UC68 | H66: AI / OCR / Finance | I66: Could-have | J66: OCR/LLM should remain supporting technology, not core MVP dependency.
A67: BR-CAL-01 | B67: Calendar | C67: Family calendar events are shared within the same Family Workspace and can be managed by Family Manager or delegated Deputy. | D67: Family Manager, Deputy, All Family Members | E67: Yes | F67: UC70, UC71 | G67: Calendar | H67: Must-have | I67: Not Started | J67: All members can view; creation/editing is permission-based.
A68: BR-ALB-01 | B68: Album | C68: Shared family album media is visible only within the same Family Workspace according to permission. | D68: All Family Members | E68: No | F68: UC72, UC73, UC74 | G68: Album | H68: Must-have | I68: Not Started | J68: Basic album upload/view remains supporting.
A69: BR-ALB-02 | B69: Album / AI | C69: Face clustering is not required for MVP; it is a future enhancement or demo-only feature. | D69: System, All Family Members | E69: No | F69: UC74, UC75 | G69: Album / AI | H69: Could-have | I69: Not Started | J69: MVP focuses on shared album and optional manual tagging.
A70: BR-ADM-01 | B70: Admin | C70: Admin Dashboard is Web only. | D70: Admin | E70: No | F70: UC01-UC08 | G70: Admin | H70: Must-have | I70: Not Started | J70: No Admin mobile app.
A71: BR-DEP-01 | B71: Deployment | C71: Docker is used only for local/demo deployment with Docker Desktop / Docker Compose. | D71: System, Admin | E71: No | F71: UC05-UC07 | G71: Docker Demo | H71: Must-have | I71: Not Started | J71: No production-grade infrastructure in current scope.
A72: BR-FUT-01 | B72: Future | C72: Kubernetes, auto-scaling, CPU/RAM/disk monitoring and backup/restore automation are Future Enhancements. | D72: Admin | E72: No | F72: UC05-UC08 | G72: Future | H72: Must-have | I72: Not Started | J72: Do not implement now.
A75: BR-SUB-10 | B75: Subscription / Feature Activation | C75: After successful upgrade payment, Premium features are activated immediately while the original subscription expiration date remains unchanged. | D75: Family Manager, System | E75: No | F75: UC76, UC77 | G75: Subscription / Feature Access | H75: Must-have | I75: Not Started | J75: Next renewal uses the Premium annual price.

Sheet API Screen DB Mapping
A1: UC ID | B1: Screen Name | C1: Platform | D1: API Endpoint | E1: Method | F1: Request DTO | G1: Response DTO | H1: DB Tables / Entities | I1: FE Owner | J1: BE Owner | K1: Status | L1: Notes
A2: UC01 | B2: Manage Basic Subscription Plans | C2: Admin Web | D2: /api/admin | E2: GET/POST/PATCH | F2: TBD | G2: TBD | H2: SubscriptionPlan, FamilyWorkspace, ProvisioningLog, AccountStatus | K2: Not Started | L2: Add exact endpoint after API design.
A3: UC02 | B3: Manage Family Workspaces and Subscription Status | C3: Admin Web | D3: /api/admin | E3: GET/POST/PATCH | F3: TBD | G3: TBD | H3: SubscriptionPlan, FamilyWorkspace, ProvisioningLog, AccountStatus | K3: Not Started | L3: Add exact endpoint after API design.
A4: UC03 | B4: Manage User Account Access | C4: Admin Web | D4: /api/admin | E4: GET/POST/PATCH | F4: TBD | G4: TBD | H4: SubscriptionPlan, FamilyWorkspace, ProvisioningLog, AccountStatus | K4: Not Started | L4: Add exact endpoint after API design.
A5: UC04 | B5: Monitor Workspace Activation Status | C5: Admin Web | D5: /api/admin | E5: GET/POST/PATCH | F5: TBD | G5: TBD | H5: SubscriptionPlan, FamilyWorkspace, ProvisioningLog, AccountStatus | K5: Not Started | L5: Add exact endpoint after API design.
A6: UC05 | B6: View Basic Service Status | C6: Admin Web | D6: /api/admin | E6: GET/POST/PATCH | F6: TBD | G6: TBD | H6: SubscriptionPlan, FamilyWorkspace, ProvisioningLog, AccountStatus | K6: Not Started | L6: Add exact endpoint after API design.
A7: UC06 | B7: View Workspace Provisioning Logs | C7: Admin Web | D7: /api/admin | E7: GET/POST/PATCH | F7: TBD | G7: TBD | H7: SubscriptionPlan, FamilyWorkspace, ProvisioningLog, AccountStatus | K7: Not Started | L7: Add exact endpoint after API design.
A8: UC07 | B8: Retry Workspace Provisioning | C8: Admin Web | D8: /api/admin | E8: GET/POST/PATCH | F8: TBD | G8: TBD | H8: SubscriptionPlan, FamilyWorkspace, ProvisioningLog, AccountStatus | K8: Not Started | L8: Add exact endpoint after API design.
A9: UC08 | B9: View Basic Subscription Summary | C9: Admin Web | D9: /api/admin | E9: GET/POST/PATCH | F9: TBD | G9: TBD | H9: SubscriptionPlan, FamilyWorkspace, ProvisioningLog, AccountStatus | K9: Not Started | L9: Add exact endpoint after API design.
A10: UC09 | B10: Register Account | C10: Flutter Mobile | D10: /api/auth | E10: POST | F10: TBD | G10: TBD | H10: User, AuthSession | K10: Not Started | L10: Add exact endpoint after API design.
A11: UC10 | B11: Verify Account | C11: Flutter Mobile | D11: /api/auth | E11: POST | F11: TBD | G11: TBD | H11: User, AuthSession | K11: Not Started | L11: Add exact endpoint after API design.
A12: UC11 | B12: Login / Logout | C12: Flutter Mobile | D12: /api/auth | E12: POST | F12: TBD | G12: TBD | H12: User, AuthSession | K12: Not Started | L12: Add exact endpoint after API design.
A13: UC12 | B13: Create Family Workspace with Default Plan | C13: Flutter Mobile | D13: /api/families | E13: GET/POST/PATCH | F13: TBD | G13: TBD | H13: Family, FamilyMember, Invitation, RolePermission | K13: Not Started | L13: Add exact endpoint after API design.
... A65: UC65 | B65: Ask AI Assistant | C65: Flutter Mobile | D65: /api/ai-assistant/chat | E65: POST | F65: AskAIRequestDto | G65: AIAnswerResponseDto | H65: AIConversation, AIMessage, User, FamilyMember, FamilyWorkspace | K65: Not Started | L65: Basic AI Q&A based on authorized family data.
A66: UC66 | B66: View AI Finance Summary | C66: Flutter Mobile | D66: /api/ai-assistant/finance-summary | E66: GET/POST | F66: AIFinanceSummaryRequestDto | G66: AIFinanceSummaryResponseDto | H66: Budget, FamilyFundLedger, LedgerEntry, SpendingSupportRequest, MemberFinancialProfile | J66: Nghĩa | K66: Not Started | L66: Must check finance permission before generating summary.
A67: UC67 | B67: View AI Task Summary | C67: Flutter Mobile | D67: /api/ai-assistant/task-summary | E67: GET/POST | F67: AITaskSummaryRequestDto | G67: AITaskSummaryResponseDto | H67: Task, TaskAssignment, TaskCompletion, RewardSettlement, FamilyMember | K67: Not Started | L67: AI summarizes task/reward settlement status only.
A68: UC68 | B68: Receive AI-based Budget and Saving Suggestions | C68: Flutter Mobile | D68: /api/ai-assistant/saving-suggestions | E68: GET/POST | F68: AISavingSuggestionRequestDto | G68: AISavingSuggestionResponseDto | H68: Budget, ExpenseCategory, LedgerEntry, FamilyFundLedger | J68: Nghĩa | K68: Not Started | L68: Advisory only; AI does not change data automatically.
A69: UC69 | B69: Request Password Reset | C69: Flutter Mobile | D69: /api/auth/forgot-password | E69: POST | F69: ForgotPasswordDto | G69: ForgotPasswordResponseDto | H69: User, PasswordResetToken | K69: Not Started | L69: Password recovery flow.
A70: UC70 | B70: Create Family Calendar Event | C70: Flutter Mobile | D70: /api/calendar/events | E70: POST | F70: CreateEventDto | G70: EventResponseDto | H70: FamilyCalendarEvent | K70: Not Started | L70: Family Manager or Deputy creates shared event.
A71: UC71 | B71: View Family Calendar Events | C71: Flutter Mobile | D71: /api/calendar/events | E71: GET | G71: List<EventResponseDto> | H71: FamilyCalendarEvent | K71: Not Started | L71: All family members view shared calendar.
A72: UC72 | B72: Upload Media to Shared Family Album | C72: Flutter Mobile | D72: /api/album/media | E72: POST | F72: UploadMediaDto | G72: MediaResponseDto | H72: FamilyAlbumMedia | K72: Not Started | L72: Basic upload/view remains supporting.
A73: UC73 | B73: View Shared Family Album Media | C73: Flutter Mobile | D73: /api/album/media | E73: GET | G73: List<MediaResponseDto> | H73: FamilyAlbumMedia | K73: Not Started | L73: Basic shared album remains supporting.
A74: UC74 | B74: Tag Family Members in Album Media | C74: Flutter Mobile | D74: /api/album/media/{id}/tags | E74: POST/PATCH | F74: TBD | G74: TBD | H74: FamilyAlbumMedia, AlbumMediaTag, FamilyMember | K74: Not Started | L74: Manual tagging is safer for MVP.
A75: UC75 | B75: Suggest Face-based Album Grouping | C75: Flutter Mobile | D75: /api/album/face-grouping/suggestions | E75: GET/POST | F75: TBD | G75: TBD | H75: FamilyAlbumMedia, FaceGroupingSuggestion, AIMessage | K75: Not Started | L75: Future/demo-only enhancement.
A76: UC76 | B76: View Current Subscription and Feature Access | C76: Flutter Mobile | D76: /api/subscriptions/current | E76: GET | F76: TBD | G76: TBD | H76: SubscriptionPlan, SubscriptionPeriod, FamilyWorkspace, FeatureAccess | K76: Not Started | L76: Shows annual plan, yearly price, expiration date, remaining days and available/locked features.
A77: UC77 | B77: Upgrade Subscription Plan | C77: Flutter Mobile | D77: /api/subscriptions/upgrade-preview; /api/subscriptions/upgrade | E77: GET/POST | F77: UpgradePreviewRequestDto; UpgradeSubscriptionRequestDto | G77: UpgradePreviewResponseDto; SubscriptionPaymentResponseDto | H77: SubscriptionPlan, SubscriptionPeriod, SubscriptionPayment, UpgradeInvoice, FamilyWorkspace, FeatureAccess | K77: Not Started | L77: Preview prorated upgrade fee before payment. Plus-to-Premium upgrade uses annual price difference and remaining days. Payment is only for subscription.
A78: UC78 | B78: Handle Subscription Expiration / Limited Access | C78: Flutter Mobile | D78: /api/subscriptions/limited-access | E78: GET/PATCH | F78: TBD | G78: TBD | H78: SubscriptionPlan, SubscriptionPeriod, FamilyWorkspace, FeatureAccess | K78: Not Started | L78: Expired annual plan locks advanced features but keeps existing data viewable.
A79: UC79 | B79: Location Sharing Settings | C79: Flutter Mobile | D79: /api/location-sharing | E79: GET/PATCH | F79: UpdateLocationSharingDto | G79: LocationSharingStatusResponseDto | H79: FamilyMember, FamilyWorkspace | K79: Not Started | L79: May be stored as member setting/profile depending on final implementation.
A80: UC80 | B80: Share / Record Member Location Point | C80: Flutter Mobile / Wearable | D80: /api/locations/member-points | E80: POST | F80: RecordMemberLocationPointDto | G80: MemberLocationPointResponseDto | H80: MemberLocationPoint, FamilyMember, FamilyWorkspace, WearableDevice | K80: Not Started | L80: Normal tracking record. Do not use SOSLocationPoint unless an SOS alert is active.
A81: UC81 | B81: View Family Member Location Tracking | C81: Flutter Mobile | D81: /api/locations/member-points | E81: GET | F81: MemberLocationQueryDto | G81: List<MemberLocationPointResponseDto> | H81: MemberLocationPoint, FamilyMember, FamilyWorkspace | K81: Not Started | L81: Used for family map/latest location/basic history with permission checks.
A82: UC82 | B82: Select Family Finance Model | C82: Flutter Mobile | D82: /api/finance/models | E82: GET/POST | F82: CreateFinanceModelDto | G82: FinanceModelResponseDto | H82: FinanceModel, FinanceJar, FamilyWorkspace | K82: Not Started | L82: Select 5 Jars, 80/20, or Custom model for family finance planning.
A83: UC83 | B83: Configure Finance Jars / Funds | C83: Flutter Mobile | D83: /api/finance/jars | E83: GET/POST/PATCH | F83: UpsertFinanceJarDto | G83: FinanceJarResponseDto | H83: FinanceJar, FinanceModel, FamilyWorkspace | K83: Not Started | L83: Configure jar/fund purpose, allocation percentage, threshold, and visibility.
A84: UC84 | B84: Categorize Income and Expense | C84: Flutter Mobile | D84: /api/finance/ledger-entries/{id}/category | E84: PATCH | F84: CategorizeLedgerEntryDto | G84: LedgerEntryResponseDto | H84: LedgerEntry, FinanceCategory, FinanceJar | K84: Not Started | L84: Manual classification is core; AI/OCR suggestion is optional.
A85: UC85 | B85: Mark Expense as Essential or Non-essential | C85: Flutter Mobile | D85: /api/finance/ledger-entries/{id}/essential-type | E85: PATCH | F85: UpdateEssentialTypeDto | G85: LedgerEntryResponseDto | H85: LedgerEntry, FinanceCategory | K85: Not Started | L85: Supports saving suggestions, budget alerts, and goal-risk analysis.
... A91: UC91 | B91: Suggest Transaction Category by AI / OCR | C91: Flutter Mobile | D91: /api/ai-assistant/transaction-category-suggestion | E91: POST | F91: TransactionCategorySuggestionRequestDto | G91: TransactionCategorySuggestionResponseDto | H91: AIMessage, LedgerEntry, FinanceCategory, FinanceJar | K91: Not Started | L91: Could-have/Future support; user must confirm final record.

Sheet Main Flow Steps
A1: x | B1: Flow Name | C1: Step No. | D1: Step Type | E1: Actor / System | F1: Action / Event | G1: System Response / Validation | H1: Related UC | I1: Related Rule ID | J1: Final Status / Output | K1: Notes
A2: F1 | B2: Account Registration & Family Workspace Setup | C2: 1 | D2: Start | E2: Guest / User | F2: Open the application and choose Register or Login. | G2: The system displays authentication screens. | H2: UC09, UC11 | I2: BR-AUTH-01, BR-AUTH-02 | J2: User starts the authentication flow. | K2: Account setup is handled before workspace setup.
A3: F1 | B3: Account Registration & Family Workspace Setup | C3: 2 | D3: User Action | E3: Guest / User | F3: Enter registration or login information. | G3: The system validates required fields, account uniqueness, and login credentials. | H3: UC09, UC11 | I3: BR-AUTH-01, BR-AUTH-02, BR-AUTH-03 | J3: Account information is submitted for validation. | K3: If the account already exists, guide the user to login, forgot password, or resend verification.
A4: F1 | B4: Account Registration & Family Workspace Setup | C4: 3 | D4: System Action | E4: System | F4: Create or authenticate the user account and handle verification if required. | G4: The system creates/authenticates the account and sets the verified or pending-verification status. | H4: UC09, UC10, UC11 | I4: BR-AUTH-01 | J4: User account is ready or waiting for verification. | K4: Verification may be simulated in demo.
A5: F1 | B5: Account Registration & Family Workspace Setup | C5: 4 | D5: System Action | E5: System | F5: Check whether the user already belongs to a Family Workspace. | G5: The system searches the user's existing workspace membership. | H5: UC11, UC12, UC13 | I5: BR-AUTH-02, BR-WS-02 | J5: Workspace membership status is identified. | K5: If the user already belongs to a workspace, route directly to the dashboard.
A6: F1 | B6: Account Registration & Family Workspace Setup | C6: 5 | D6: System Action | E6: System | F6: If the user has no workspace, show Family Workspace setup options. | G6: The system displays two options: create a new Family Workspace or join an existing workspace by invitation link. | H6: UC12, UC13 | I6: BR-WS-01, BR-INV-01 | J6: Workspace setup options are displayed. | K6: Do not send the user to an empty dashboard before workspace setup.
A7: F1 | B7: Account Registration & Family Workspace Setup | C7: 6 | D7: User Action | E7: Authenticated User | F7: Choose Create New Family Workspace or Join by Invitation Link. | G7: The system validates submitted workspace information or invitation token. | H7: UC12, UC13 | I7: BR-WS-01, BR-INV-01 | J7: A create-workspace or join-workspace request is submitted. | K7: Creator and invited-member paths are shown as separate branches in the swimlane.
A8: F1 | B8: Account Registration & Family Workspace Setup | C8: 7 | D8: System Action | E8: System | F8: Create a new Family Workspace or add the invited user to an existing workspace. | G8: If creating a workspace, the system creates it and assigns the creator as the only primary Family Manager. If joining by invitation, the system adds the user as a Family Member. | H8: UC12, UC13 | I8: BR-WS-01, BR-ROLE-01, BR-INV-01 | J8: User is linked to a valid Family Workspace. | K8: Only the workspace creator becomes the primary Family Manager.
A9: F1 | B9: Account Registration & Family Workspace Setup | C9: 8 | D9: System Action | E9: System | F9: Apply the default Free/Basic subscription status to a newly created workspace. | G9: The system initializes the default subscription status; renewal or upgrade is handled later after activation. | H9: UC12, UC01, UC02 | I9: BR-SUB-01, BR-WS-02 | J9: Default subscription status is applied. | K9: Subscription management is not part of initial onboarding.
A10: F1 | B10: Account Registration & Family Workspace Setup | C10: 9 | D10: System Action | E10: System | F10: Activate or validate workspace access according to verification, invitation, and subscription status. | G10: The system updates access status and records setup logs if needed. | H10: UC12, UC13, UC04 | I10: BR-WS-02, BR-DEP-01 | J10: Workspace access is ready. | K10: Docker/container provisioning can remain local/demo for MVP.
A11: F1 | B11: Account Registration & Family Workspace Setup | C11: 10 | D11: End | E11: System | F11: Route the user to the correct Family Dashboard. | G11: The system routes the Family Manager to workspace home and invited members to the member dashboard. | H11: UC11, UC12, UC13 | I11: BR-AUTH-02, BR-WS-02 | J11: User has an account and belongs to a valid Family Workspace. | K11: Final state: authenticated user can access a workspace-specific dashboard.
A12: F2 | B12: Member, Relationship & Delegated Permission Management | C12: 1 | D12: Start | E12: Family Manager | F12: Open the member management screen. | G12: The system checks Family Manager permission. | H12: UC20 | I12: BR-AUTH-02, BR-ROLE-01 | J12: Member management screen is available if permission is valid. | K12: Only the primary Family Manager can manage member access directly.
A13: F2 | B13: Member, Relationship & Delegated Permission Management | C13: 2 | D13: User Action | E13: Family Manager | F13: Create an invitation link for a new member. | G13: The system generates an invitation code with family context. | H13: UC15 | I13: BR-INV-01 | J13: Invitation link is created. | K13: The invited user will not become another Family Manager by default.
... A106: SF3 | B106: Subscription Plan and Feature Access Management | C106: 7 | D106: End | E106: System | F106: Display updated plan, status, remaining days and available/locked features. | G106: The system keeps annual subscription status consistent with feature access across modules. | H106: UC76-UC78 | I106: BR-SUB-01, BR-SUB-05, BR-SUB-07, BR-SUB-10 | J106: Subscription management flow is completed. | K106: Final state: annual subscription is clear and separated from Family Fund Ledger.

Sheet VI - Dictionary
A1: English | B1: Vietnamese
A2: Must-have | B2: Bắt buộc
A3: Should-have | B3: Nên có
A4: Could-have | B4: Có thể có
A5: Not Started | B5: Chưa bắt đầu
A6: Keep | B6: Giữ trong scope
A7: Could-have / Do after core | B7: Có thể có / Làm sau core
A8: Core | B8: Luồng chính
A9: Supporting | B9: Luồng hỗ trợ
A10: Yes | B10: Có
A11: No | B11: Không
A12: N/A | B12: Không áp dụng
... A46: System | B46: Hệ thống

Sheet Subscription Plan Matrix
A1: Family Care - Subscription Plan Matrix (Annual Billing Only)
A3: Feature / Capability | B3: Free | C3: Plus Annual | D3: Premium Annual | E3: Related UC / Rule | F3: Notes
A4: Price | B4: 0đ | C4: 990.000đ/year | D4: 1.990.000đ/year | E4: BR-SUB-08 | F4: Example pricing; can be adjusted by Admin.
A5: Billing cycle | B5: No paid cycle | C5: Annual only | D5: Annual only | E5: BR-SUB-08 | F5: Monthly billing is out of scope for MVP.
A6: Family workspace | B6: Yes | C6: Yes | D6: Yes | E6: UC12, BR-SUB-02 | F6: Free plan starts by default after workspace creation.
A7: Member management | B7: Basic | C7: Full | D7: Full | E7: UC14-UC20 | F7: Member count is not the main selling point.
A8: Task management | B8: Basic | C8: Full | D8: Full | E8: UC37-UC49 | F8: Plus unlocks full recurring task/reward settlement management.
A9: Internal allowance / reward record | B9: Basic | C9: Full | D9: Full | E9: UC33, UC45-UC49, BR-FIN-07 | F9: Internal record only, no real cash-out.
A10: Basic finance tracking | B10: Yes | C10: Yes | D10: Yes | E10: UC21-UC29 | F10: Core finance should remain available at basic level.
A11: Budget planning | B11: Basic | C11: Full | D11: Full | E11: UC24-UC26 | F11: Plus is the main family management plan.
A12: Planned-vs-actual report | B12: No / Basic preview | C12: Yes | D12: Yes | E12: UC29, BR-SUB-03 | F12: Key value for Finance after Review 1.
A13: Budget alerts | B13: No | C13: Yes | D13: Yes | E13: UC30, BR-SUB-03 | F13: Raised to Must-have in core finance scope.
A14: Export finance report | B14: No | C14: Yes | D14: Yes / Advanced | E14: BR-SUB-03, BR-SUB-07 | F14: Can be implemented as PDF/Excel export later.
... A29: Main positioning | B29: Trial / Basic | C29: Family Management | D29: AI + Safety | E29: BR-SUB-02 to BR-SUB-04 | F29: Plans are differentiated by value and capability.

Sheet VI - Use Case Tracker
A1: Mã UC | B1: Tên Use Case | C1: Luồng chính | D1: Module | E1: Actor chính | F1: Mô tả / Mục tiêu | G1: Độ ưu tiên | H1: Trạng thái | I1: Người phụ trách | J1: Mã rule liên quan | K1: Ghi chú | L1: Quyết định scope cuối
A2: =IF('Use Case Tracker'!A2="","",'Use Case Tracker'!A2) -> UC01 | B2: =IFERROR(__xludf.DUMMYFUNCTION("IF('Use Case Tracker'!B2="""","""",IFERROR(GOOGLETRANSLATE('Use Case Tracker'!B2,""en"",""vi""),'Use Case Tracker'!B2))"),"Quản lý gói đăng ký và quyền truy cập tính năng") -> Quản lý gói đăng ký và quyền truy cập tính năng | C2: =IFERROR(__xludf.DUMMYFUNCTION("IF('Use Case Tracker'!C2="""","""",IFERROR(GOOGLETRANSLATE('Use Case Tracker'!C2,""en"",""vi""),'Use Case Tracker'!C2))"),"Hỗ trợ quản trị/Docker") -> Hỗ trợ quản trị/Docker | D2: =IFERROR(__xludf.DUMMYFUNCTION("IF('Use Case Tracker'!D2="""","""",IFERROR(GOOGLETRANSLATE('Use Case Tracker'!D2,""en"",""vi""),'Use Case Tracker'!D2))"),"Đăng ký") -> Đăng ký | E2: =IFERROR(__xludf.DUMMYFUNCTION("IF('Use Case Tracker'!E2="""","""",IFERROR(GOOGLETRANSLATE('Use Case Tracker'!E2,""en"",""vi""),'Use Case Tracker'!E2))"),"Quản trị viên") -> Quản trị viên | F2: =IFERROR(__xludf.DUMMYFUNCTION("IF('Use Case Tracker'!F2="""","""",IFERROR(GOOGLETRANSLATE('Use Case Tracker'!F2,""en"",""vi""),'Use Case Tracker'!F2))"),"Quản trị viên tạo/cập nhật/vô hiệu hóa các gói Miễn phí, Plus và Premium. Các gói trả phí chỉ được tính phí hàng năm. Mỗi gói xác định giá hàng năm và quyền truy cập vào các tính năng như báo cáo tài chính, phân tích AI, tính năng an toàn SOS, hỗ trợ thiế"&"t bị đeo, khả năng lưu trữ và xuất dữ liệu.") -> Quản trị viên tạo/cập nhật/vô hiệu hóa các gói Miễn phí, Plus và Premium. Các gói trả phí chỉ được tính phí hàng năm. Mỗi gói xác định giá hàng năm và quyền truy cập vào các tính năng như báo cáo tài chính, phân tích AI, tính năng an toàn SOS, hỗ trợ thiết bị đeo, khả năng lưu trữ và xuất dữ liệu. | G2: =IF('Use Case Tracker'!G2="","",SWITCH('Use Case Tracker'!G2,"Must-have","Bắt buộc","Should-have","Nên có","Could-have","Có thể có",'Use Case Tracker'!G2)) -> Bắt buộc | H2: =IF('Use Case Tracker'!H2="","",SWITCH('Use Case Tracker'!H2,"Not Started","Chưa bắt đầu","In Progress","Đang làm","Done","Hoàn thành",'Use Case Tracker'!H2)) -> Chưa bắt đầu | L2: =IF('Use Case Tracker'!L2="","",SWITCH('Use Case Tracker'!L2,"Keep","Giữ trong scope","Could-have / Do after core","Có thể có / Làm sau core",'Use Case Tracker'!L2)) -> Giữ trong scope
A3: =IF('Use Case Tracker'!A3="","",'Use Case Tracker'!A3) -> UC02 | B3: =IFERROR(__xludf.DUMMYFUNCTION("IF('Use Case Tracker'!B3="""","""",IFERROR(GOOGLETRANSLATE('Use Case Tracker'!B3,""en"",""vi""),'Use Case Tracker'!B3))"),"Quản lý không gian làm việc gia đình và trạng thái đăng ký") -> Quản lý không gian làm việc gia đình và trạng thái đăng ký | C3: =IFERROR(__xludf.DUMMYFUNCTION("IF('Use Case Tracker'!C3="""","""",IFERROR(GOOGLETRANSLATE('Use Case Tracker'!C3,""en"",""vi""),'Use Case Tracker'!C3))"),"Hỗ trợ quản trị/Docker") -> Hỗ trợ quản trị/Docker | D3: =IFERROR(__xludf.DUMMYFUNCTION("IF('Use Case Tracker'!D3="""","""",IFERROR(GOOGLETRANSLATE('Use Case Tracker'!D3,""en"",""vi""),'Use Case Tracker'!D3))"),"Quản trị viên") -> Quản trị viên | E3: =IFERROR(__xludf.DUMMYFUNCTION("IF('Use Case Tracker'!E3="""","""",IFERROR(GOOGLETRANSLATE('Use Case Tracker'!E3,""en"",""vi""),'Use Case Tracker'!E3))"),"Quản trị viên") -> Quản trị viên | F3: =IFERROR(__xludf.DUMMYFUNCTION("IF('Use Case Tracker'!F3="""","""",IFERROR(GOOGLETRANSLATE('Use Case Tracker'!F3,""en"",""vi""),'Use Case Tracker'!F3))"),"Quản trị viên xem không gian làm việc, Trình quản lý Gia đình chính, trạng thái đăng ký và kích hoạt.") -> Quản trị viên xem không gian làm việc, Trình quản lý Gia đình chính, trạng thái đăng ký và kích hoạt. | G3: =IF('Use Case Tracker'!G3="","",SWITCH('Use Case Tracker'!G3,"Must-have","Bắt buộc","Should-have","Nên có","Could-have","Có thể có",'Use Case Tracker'!G3)) -> Bắt buộc | H3: =IF('Use Case Tracker'!H3="","",SWITCH('Use Case Tracker'!H3,"Not Started","Chưa bắt đầu","In Progress","Đang làm","Done","Hoàn thành",'Use Case Tracker'!H3)) -> Chưa bắt đầu | I3: =IF('Use Case Tracker'!I3="","",'Use Case Tracker'!I3) | J3: =IF('Use Case Tracker'!J3="","",'Use Case Tracker'!J3) -> BR-SUB-01, BR-WS-02 | K3: =IFERROR(__xludf.DUMMYFUNCTION("IF('Use Case Tracker'!K3="""","""",IFERROR(GOOGLETRANSLATE('Use Case Tracker'!K3,""en"",""vi""),'Use Case Tracker'!K3))"),"") | L3: =IF('Use Case Tracker'!L3="","",SWITCH('Use Case Tracker'!L3,"Keep","Giữ trong scope","Could-have / Do after core","Có thể có / Làm sau core",'Use Case Tracker'!L3)) -> Giữ trong scope
A4: =IF('Use Case Tracker'!A4="","",'Use Case Tracker'!A4) -> UC03 | B4: =IFERROR(__xludf.DUMMYFUNCTION("IF('Use Case Tracker'!B4="""","""",IFERROR(GOOGLETRANSLATE('Use Case Tracker'!B4,""en"",""vi""),'Use Case Tracker'!B4))"),"Quản lý quyền truy cập tài khoản người dùng") -> Quản lý quyền truy cập tài khoản người dùng | C4: =IFERROR(__xludf.DUMMYFUNCTION("IF('Use Case Tracker'!C4="""","""",IFERROR(GOOGLETRANSLATE('Use Case Tracker'!C4,""en"",""vi""),'Use Case Tracker'!C4))"),"Hỗ trợ quản trị/Docker") -> Hỗ trợ quản trị/Docker | D4: =IFERROR(__xludf.DUMMYFUNCTION("IF('Use Case Tracker'!D4="""","""",IFERROR(GOOGLETRANSLATE('Use Case Tracker'!D4,""en"",""vi""),'Use Case Tracker'!D4))"),"Quản trị viên") -> Quản trị viên | E4: =IFERROR(__xludf.DUMMYFUNCTION("IF('Use Case Tracker'!E4="""","""",IFERROR(GOOGLETRANSLATE('Use Case Tracker'!E4,""en"",""vi""),'Use Case Tracker'!E4))"),"Quản trị viên") -> Quản trị viên | F4: =IFERROR(__xludf.DUMMYFUNCTION("IF('Use Case Tracker'!F4="""","""",IFERROR(GOOGLETRANSLATE('Use Case Tracker'!F4,""en"",""vi""),'Use Case Tracker'!F4))"),"Quản trị viên có thể khóa/mở khóa/hạn chế/khôi phục quyền truy cập của người dùng khi cần thiết.") -> Quản trị viên có thể khóa/mở khóa/hạn chế/khôi phục quyền truy cập của người dùng khi cần thiết. | G4: =IF('Use Case Tracker'!G4="","",SWITCH('Use Case Tracker'!G4,"Must-have","Bắt buộc","Should-have","Nên có","Could-have","Có thể có",'Use Case Tracker'!G4)) -> Bắt buộc | H4: =IF('Use Case Tracker'!H4="","",SWITCH('Use Case Tracker'!H4,"Not Started","Chưa bắt đầu","In Progress","Đang làm","Done","Hoàn thành",'Use Case Tracker'!H4)) -> Chưa bắt đầu | I4: =IF('Use Case Tracker'!I4="","",'Use Case Tracker'!I4) | J4: =IF('Use Case Tracker'!J4="","",'Use Case Tracker'!J4) -> BR-ADM-01, BR-AUTH-02 | K4: =IFERROR(__xludf.DUMMYFUNCTION("IF('Use Case Tracker'!K4="""","""",IFERROR(GOOGLETRANSLATE('Use Case Tracker'!K4,""en"",""vi""),'Use Case Tracker'!K4))"),"") | L4: =IF('Use Case Tracker'!L4="","",SWITCH('Use Case Tracker'!L4,"Keep","Giữ trong scope","Could-have / Do after core","Có thể có / Làm sau core",'Use Case Tracker'!L4)) -> Giữ trong scope
A5: =IF('Use Case Tracker'!A5="","",'Use Case Tracker'!A5) -> UC04 | B5: =IFERROR(__xludf.DUMMYFUNCTION("IF('Use Case Tracker'!B5="""","""",IFERROR(GOOGLETRANSLATE('Use Case Tracker'!B5,""en"",""vi""),'Use Case Tracker'!B5))"),"Giám sát trạng thái kích hoạt không gian làm việc") -> Giám sát trạng thái kích hoạt không gian làm việc | C5: =IFERROR(__xludf.DUMMYFUNCTION("IF('Use Case Tracker'!C5="""","""",IFERROR(GOOGLETRANSLATE('Use Case Tracker'!C5,""en"",""vi""),'Use Case Tracker'!C5))"),"Hỗ trợ quản trị/Docker") -> Hỗ trợ quản trị/Docker | D5: =IFERROR(__xludf.DUMMYFUNCTION("IF('Use Case Tracker'!D5="""","""",IFERROR(GOOGLETRANSLATE('Use Case Tracker'!D5,""en"",""vi""),'Use Case Tracker'!D5))"),"Quản trị viên") -> Quản trị viên | E5: =IFERROR(__xludf.DUMMYFUNCTION("IF('Use Case Tracker'!E5="""","""",IFERROR(GOOGLETRANSLATE('Use Case Tracker'!E5,""en"",""vi""),'Use Case Tracker'!E5))"),"Quản trị viên") -> Quản trị viên | F5: =IFERROR(__xludf.DUMMYFUNCTION("IF('Use Case Tracker'!F5="""","""",IFERROR(GOOGLETRANSLATE('Use Case Tracker'!F5,""en"",""vi""),'Use Case Tracker'!F5))"),"Quản trị viên kiểm tra trạng thái hoạt động/đang chờ xử lý/bị tạm dừng/thất bại/hết hạn của không gian làm việc.") -> Quản trị viên kiểm tra trạng thái hoạt động/đang chờ xử lý/bị tạm dừng/thất bại/hết hạn của không gian làm việc. | G5: =IF('Use Case Tracker'!G5="","",SWITCH('Use Case Tracker'!G5,"Must-have","Bắt buộc","Should-have","Nên có","Could-have","Có thể có",'Use Case Tracker'!G5)) -> Bắt buộc | H5: =IF('Use Case Tracker'!H5="","",SWITCH('Use Case Tracker'!H5,"Not Started","Chưa bắt đầu","In Progress","Đang làm","Done","Hoàn thành",'Use Case Tracker'!H5)) -> Chưa bắt đầu | I5: =IF('Use Case Tracker'!I5="","",'Use Case Tracker'!I5) | J5: =IF('Use Case Tracker'!J5="","",'Use Case Tracker'!J5) -> BR-WS-02, BR-DEP-01 | K5: =IFERROR(__xludf.DUMMYFUNCTION("IF('Use Case Tracker'!K5="""","""",IFERROR(GOOGLETRANSLATE('Use Case Tracker'!K5,""en"",""vi""),'Use Case Tracker'!K5))"),"") | L5: =IF('Use Case Tracker'!L5="","",SWITCH('Use Case Tracker'!L5,"Keep","Giữ trong scope","Could-have / Do after core","Có thể có / Làm sau core",'Use Case Tracker'!L5)) -> Giữ trong scope
A6: =IF('Use Case Tracker'!A6="","",'Use Case Tracker'!A6) -> UC05 | B6: =IFERROR(__xludf.DUMMYFUNCTION("IF('Use Case Tracker'!B6="""","""",IFERROR(GOOGLETRANSLATE('Use Case Tracker'!B6,""en"",""vi""),'Use Case Tracker'!B6))"),"Xem trạng thái dịch vụ cơ bản") -> Xem trạng thái dịch vụ cơ bản | C6: =IFERROR(__xludf.DUMMYFUNCTION("IF('Use Case Tracker'!C6="""","""",IFERROR(GOOGLETRANSLATE('Use Case Tracker'!C6,""en"",""vi""),'Use Case Tracker'!C6))"),"Hỗ trợ quản trị/Docker") -> Hỗ trợ quản trị/Docker | D6: =IFERROR(__xludf.DUMMYFUNCTION("IF('Use Case Tracker'!D6="""","""",IFERROR(GOOGLETRANSLATE('Use Case Tracker'!D6,""en"",""vi""),'Use Case Tracker'!D6))"),"Quản trị viên") -> Quản trị viên | E6: =IFERROR(__xludf.DUMMYFUNCTION("IF('Use Case Tracker'!E6="""","""",IFERROR(GOOGLETRANSLATE('Use Case Tracker'!E6,""en"",""vi""),'Use Case Tracker'!E6))"),"Quản trị viên") -> Quản trị viên | F6: =IFERROR(__xludf.DUMMYFUNCTION("IF('Use Case Tracker'!F6="""","""",IFERROR(GOOGLETRANSLATE('Use Case Tracker'!F6,""en"",""vi""),'Use Case Tracker'!F6))"),"Quản trị viên có thể xem trạng thái dịch vụ demo cơ bản như Backend, Admin Web, API và Database.") -> Quản trị viên có thể xem trạng thái dịch vụ demo cơ bản như Backend, Admin Web, API và Database. | G6: =IF('Use Case Tracker'!G6="","",SWITCH('Use Case Tracker'!G6,"Must-have","Bắt buộc","Should-have","Nên có","Could-have","Có thể có",'Use Case Tracker'!G6)) -> Nên có | H6: =IF('Use Case Tracker'!H6="","",SWITCH('Use Case Tracker'!H6,"Not Started","Chưa bắt đầu","In Progress","Đang làm","Done","Hoàn thành",'Use Case Tracker'!H6)) -> Chưa bắt đầu | I6: =IF('Use Case Tracker'!I6="","",'Use Case Tracker'!I6) | J6: =IF('Use Case Tracker'!J6="","",'Use Case Tracker'!J6) -> BR-DEP-01, BR-FUT-01 | K6: =IFERROR(__xludf.DUMMYFUNCTION("IF('Use Case Tracker'!K6="""","""",IFERROR(GOOGLETRANSLATE('Use Case Tracker'!K6,""en"",""vi""),'Use Case Tracker'!K6))"),"") | L6: =IF('Use Case Tracker'!L6="","",SWITCH('Use Case Tracker'!L6,"Keep","Giữ trong scope","Could-have / Do after core","Có thể có / Làm sau core",'Use Case Tracker'!L6)) -> Giữ trong scope
A7: =IF('Use Case Tracker'!A7="","",'Use Case Tracker'!A7) -> UC06 | B7: =IFERROR(__xludf.DUMMYFUNCTION("IF('Use Case Tracker'!B7="""","""",IFERROR(GOOGLETRANSLATE('Use Case Tracker'!B7,""en"",""vi""),'Use Case Tracker'!B7))"),"Xem nhật ký cấp phép không gian làm việc") -> Xem nhật ký cấp phép không gian làm việc | C7: =IFERROR(__xludf.DUMMYFUNCTION("IF('Use Case Tracker'!C7="""","""",IFERROR(GOOGLETRANSLATE('Use Case Tracker'!C7,""en"",""vi""),'Use Case Tracker'!C7))"),"Hỗ trợ quản trị/Docker") -> Hỗ trợ quản trị/Docker | D7: =IFERROR(__xludf.DUMMYFUNCTION("IF('Use Case Tracker'!D7="""","""",IFERROR(GOOGLETRANSLATE('Use Case Tracker'!D7,""en"",""vi""),'Use Case Tracker'!D7))"),"Quản trị viên") -> Quản trị viên | E7: =IFERROR(__xludf.DUMMYFUNCTION("IF('Use Case Tracker'!E7="""","""",IFERROR(GOOGLETRANSLATE('Use Case Tracker'!E7,""en"",""vi""),'Use Case Tracker'!E7))"),"Quản trị viên") -> Quản trị viên | F7: =IFERROR(__xludf.DUMMYFUNCTION("IF('Use Case Tracker'!F7="""","""",IFERROR(GOOGLETRANSLATE('Use Case Tracker'!F7,""en"",""vi""),'Use Case Tracker'!F7))"),"Quản trị viên xem nhật ký cấp phép cơ bản về các lỗi kích hoạt không gian làm việc/khởi động bản demo.") -> Quản trị viên xem nhật ký cấp phép cơ bản về các lỗi kích hoạt không gian làm việc/khởi động bản demo. | G7: =IF('Use Case Tracker'!G7="","",SWITCH('Use Case Tracker'!G7,"Must-have","Bắt buộc","Should-have","Nên có","Could-have","Có thể có",'Use Case Tracker'!G7)) -> Nên có | H7: =IF('Use Case Tracker'!H7="","",SWITCH('Use Case Tracker'!H7,"Not Started","Chưa bắt đầu","In Progress","Đang làm","Done","Hoàn thành",'Use Case Tracker'!H7)) -> Chưa bắt đầu | J7: =IF('Use Case Tracker'!J7="","",'Use Case Tracker'!J7) -> BR-DEP-01 | K7: =IFERROR(__xludf.DUMMYFUNCTION("IF('Use Case Tracker'!K7="""","""",IFERROR(GOOGLETRANSLATE('Use Case Tracker'!K7,""en"",""vi""),'Use Case Tracker'!K7))"),"") | L7: =IF('Use Case Tracker'!L7="","",SWITCH('Use Case Tracker'!L7,"Keep","Giữ trong scope","Could-have / Do after core","Có thể có / Làm sau core",'Use Case Tracker'!L7)) -> Giữ trong scope
